Workbook

Sheet 01_Summary
A1: ADU Materials Estimate V2 — Зведений по фазам
A3: Проєкт | B3: Garage Conversion to ADU
A4: Локація | B4: Menlo Park, California 94025
A5: Total ADU Area | B5: 315 sq ft (15' × 21')
A6: Ceiling | B6: Vaulted: 8 ft edges / 12 ft center
A7: Raised Floor | B7: 10 inches
A8: Estimate Type | B8: Materials only (no labor / fees / tax per ТЗ §32)
A9: Approach | B9: Construction phases (shell-to-finish, coробка готова)
A10: Sources | B10: Home Depot / IKEA / Best Buy / Amazon / Special Order
A11: Дата створення | B11: 2026-05-28
A12: Статус | B12: V2 Draft — phase-based, потребує заповнення цін
A15: Розподіл по construction phases
A16: # | B16: Phase / Лист | C16: Phase Label | D16: Опис | E16: Items | F16: Subtotal ($) | G16: % of Total
A17: 1 | B17: 02_Site_Exterior_Utilities | C17: Site / Trenching | D17: Phase 1 — Site & Exterior Utilities (§19) | E17: 49 | F17: ='02_Site_Exterior_Utilities'!K55 | G17: =IF($F$37=0,"",F17/$F$37)
A18: 2 | B18: 03_Raised_Floor_System | C18: Floor System | D18: Phase 2 — Raised Floor System (§17) | E18: 22 | F18: ='03_Raised_Floor_System'!K28 | G18: =IF($F$37=0,"",F18/$F$37)
A19: 3 | B19: 04_Framing | C19: Framing | D19: Phase 3 — Framing (§18) | E19: 23 | F19: ='04_Framing'!K29 | G19: =IF($F$37=0,"",F19/$F$37)
A20: 4 | B20: 05_Doors_Windows | C20: Openings | D20: Phase 4 — Doors & Windows / Openings (§25) | E20: 30 | F20: ='05_Doors_Windows'!K36 | G20: =IF($F$37=0,"",F20/$F$37)
A21: 5 | B21: 06_Plumbing_Roughin | C21: Plumbing R-I | D21: Phase 5 — Plumbing Rough-in (§20) | E21: 34 | F21: ='06_Plumbing_Roughin'!K40 | G21: =IF($F$37=0,"",F21/$F$37)
A22: 6 | B22: 07_Electrical_Roughin | C22: Electrical R-I | D22: Phase 6 — Electrical Rough-in (§21) | E22: 37 | F22: ='07_Electrical_Roughin'!K43 | G22: =IF($F$37=0,"",F22/$F$37)
A23: 7 | B23: 08_HVAC_MiniSplit | C23: HVAC | D23: Phase 7 — HVAC Mini-Split (§22) | E23: 24 | F23: ='08_HVAC_MiniSplit'!K30 | G23: =IF($F$37=0,"",F23/$F$37)
A24: 8 | B24: 09_Insulation | C24: Insulation | D24: Phase 8 — Insulation (§23) | E24: 16 | F24: ='09_Insulation'!K22 | G24: =IF($F$37=0,"",F24/$F$37)
A25: 9 | B25: 10_Drywall | C25: Drywall | D25: Phase 9 — Drywall (§24) | E25: 20 | F25: ='10_Drywall'!K26 | G25: =IF($F$37=0,"",F25/$F$37)
A26: 10 | B26: 11_Paint | C26: Paint | D26: Phase 10 — Paint (§27) | E26: 20 | F26: ='11_Paint'!K26 | G26: =IF($F$37=0,"",F26/$F$37)
A27: 11 | B27: 12_Flooring_Trim | C27: Flooring | D27: Phase 11 — Flooring & Trim (§26) | E27: 14 | F27: ='12_Flooring_Trim'!K20 | G27: =IF($F$37=0,"",F27/$F$37)
A28: 12 | B28: 13_Kitchen_Cabinets | C28: Cabinetry | D28: Phase 12 — Kitchen Cabinets & Countertop (§11) | E28: 32 | F28: ='13_Kitchen_Cabinets'!K38 | G28: =IF($F$37=0,"",F28/$F$37)
A29: 13 | B29: 14_Bathroom_Fixtures | C29: Finish — Fixtures | D29: Phase 13 — Bathroom Fixtures (§14) | E29: 42 | F29: ='14_Bathroom_Fixtures'!K48 | G29: =IF($F$37=0,"",F29/$F$37)
A30: 14 | B30: 15_Closet_System | C30: Furnishing | D30: Phase 14 — Closet System (§13) | E30: 17 | F30: ='15_Closet_System'!K23 | G30: =IF($F$37=0,"",F30/$F$37)
A31: 15 | B31: 16_Water_Heater | C31: MEP — Water Heater | D31: Phase 15 — Water Heater & Utility (§16) | E31: 17 | F31: ='16_Water_Heater'!K23 | G31: =IF($F$37=0,"",F31/$F$37)
A32: 16 | B32: 17_Appliances | C32: Appliances | D32: Phase 16 — Appliances (§28) | E32: 17 | F32: ='17_Appliances'!K23 | G32: =IF($F$37=0,"",F32/$F$37)
A33: 17 | B33: 18_Furniture_IKEA | C33: Furniture | D33: Phase 17 — Furniture (§29) | E33: 27 | F33: ='18_Furniture_IKEA'!K33 | G33: =IF($F$37=0,"",F33/$F$37)
A34: 18 | B34: 19_Special_Orders | C34: Special Order | D34: Cross-reference — Special Orders (§31.5) | E34: 7 | F34: ='19_Special_Orders'!K13 | G34: =IF($F$37=0,"",F34/$F$37)
A35: 19 | B35: 20_Verification_Items | C35: Verification | D35: Cross-reference — Verification Items (§33) | E35: 26 | F35: ='20_Verification_Items'!K32 | G35: =IF($F$37=0,"",F35/$F$37)
B37: GRAND TOTAL | F37: =SUM(F17:F35)
A39: ℹ️ Phase 19 (Special Orders) = CROSS-REFERENCE only. Items already in respective phases (Phase 4, 7, 15, 16). Не додає до Grand Total.
A40: ℹ️ Phase 20 (Verification Items) = 26 пунктів §33 not priced, but may change quantities after field verification.
A42: 📊 Reference Totals (НЕ включено в Grand Total)
A43: Item | B43: $
A44: Grand Total — Materials Only | B44: =F37
A45: Estimated CA Sales Tax 9.375% (reference) | B45: =F37*0.09375
A46: Materials + Tax (reference) | B46: =F37*1.09375
...

Sheet 02_Site_Exterior_Utilities
A1: Phase 1 — Site & Exterior Utilities (§19)
A2: Sewer 100ft + Water 100ft + Electric 50ft
A4: # | B4: Phase | C4: Категорія | D4: Item / Material | E4: Spec / Опис | F4: Unit | G4: Qty (Low) | H4: Qty (Mid) | I4: Qty (High) | J4: Unit Price ($) | K4: Total ($) | L4: Source | M4: SKU / Model | N4: URL | O4: Status | P4: Confidence | Q4: Notes
A5: 1 | B5: Site / Trenching | C5: Sewer | D5: Sewer Pipe 4" | E5: SDR35 PVC, 10 ft pieces | F5: linear ft | G5: 100 | H5: 110 | I5: 120 | J5: 2.4 | K5: =IF(OR(H5="",J5="",J5=0),"",H5*J5) | L5: Home Depot | M5: Charlotte / JM Eagle 4" SDR35 | N5: https://www.homedepot.com/p/Charlotte-Pipe-4-in-x-10-ft-White-PVC-Sewer-Main-SDR35-Pipe-with-Gaskete-S-M-06004G-1400/203504420 | O5: Confirmed | P5: high | Q5: 100 ft підтверджено власником | $2.40/LF. Charlotte SDR35 10ft pieces ~$24 | Ціна збір: 2026-05-28
A6: 2 | B6: Site / Trenching | C6: Sewer | D6: Sewer Couplings 4" | E6: Hub couplings | F6: pcs | G6: 4 | H6: 6 | I6: 8 | J6: 5.5 | K6: =IF(OR(H6="",J6="",J6=0),"",H6*J6) | L6: Home Depot | M6: Generic SDR35 4" | O6: Confirmed | P6: medium | Q6: Hub couplings | Ціна збір: 2026-05-28
A7: 3 | B7: Site / Trenching | C7: Sewer | D7: Sewer Elbows 45°/90° | E7: ABS/PVC short radius | F7: pcs | G7: 4 | H7: 6 | I7: 8 | J7: 7.5 | K7: =IF(OR(H7="",J7="",J7=0),"",H7*J7) | L7: Home Depot | M7: Generic SDR35 4" | O7: Confirmed | P7: medium | Q7: 45° + 90° short radius mix | Ціна збір: 2026-05-28
A8: 4 | B8: Site / Trenching | C8: Sewer | D8: Long-radius Sweep 4" | E8: Для slope (рекомендовано) | F8: pcs | G8: 2 | H8: 3 | I8: 4 | J8: 15 | K8: =IF(OR(H8="",J8="",J8=0),"",H8*J8) | L8: Home Depot | M8: Generic SDR35 4" | O8: TBD | P8: medium | Q8: Slope to be verified by plumber / local code | Long-radius sweep — slope verify by plumber | Ціна збір: 2026-05-28
A9: 5 | B9: Site / Trenching | C9: Sewer | D9: Wye Fittings 4" | E9: Branch tie-ins | F9: pcs | G9: 2 | H9: 3 | I9: 4 | J9: 15 | K9: =IF(OR(H9="",J9="",J9=0),"",H9*J9) | L9: Home Depot | M9: Generic SDR35 4" | O9: Confirmed | P9: medium | Q9: Wye 4×4×4 | Ціна збір: 2026-05-28
A10: 6 | B10: Site / Trenching | C10: Sewer | D10: Sewer Cleanouts 4" | E10: Body + plug + collar | F10: pcs | G10: 2 | H10: 3 | I10: 4 | J10: 28 | K10: =IF(OR(H10="",J10="",J10=0),"",H10*J10) | L10: Home Depot | M10: Generic 4" cleanout | O10: Confirmed | P10: medium | Q10: Depends on route and bends — підвищено Mid до 3 | Body + plug + collar. Mid підвищено до 3 | Ціна збір: 2026-05-28
A11: 7 | B11: Site / Trenching | C11: Sewer | D11: Primer / Cement ABS-PVC | E11: Solvent weld | F11: cans | G11: 2 | H11: 3 | I11: 4 | J11: 12 | K11: =IF(OR(H11="",J11="",J11=0),"",H11*J11) | L11: Home Depot | M11: Oatey / Christy's | O11: Confirmed | P11: medium | Q11: Primer+cement combo | Ціна збір: 2026-05-28
A12: 8 | B12: Site / Trenching | C12: Sewer | D12: Sand Bedding (3" under pipe) | E12: Cushion under pipe | F12: cu yd | G12: 1 | H12: 2 | I12: 3 | J12: 35 | K12: =IF(OR(H12="",J12="",J12=0),"",H12*J12) | L12: Aggregate yard | M12: Aggregate yard | O12: Confirmed | P12: medium | Q12: Recommended — verify if required by local code / utility | Sand bedding — verify if required | Ціна збір: 2026-05-28
A13: 9 | B13: Site / Trenching | C13: Sewer | D13: Gravel / Bedding (above pipe) | E13: 3/4" rock | F13: cu yd | G13: 1 | H13: 2 | I13: 3 | J13: 45 | K13: =IF(OR(H13="",J13="",J13=0),"",H13*J13) | L13: Aggregate yard | M13: Aggregate yard | O13: TBD | P13: medium | Q13: 3/4" rock backfill | Ціна збір: 2026-05-28
A14: 10 | B14: Site / Trenching | C14: Sewer | D14: Tracer Wire 14 AWG | E14: Locator wire для non-metallic | F14: linear ft | G14: 100 | H14: 110 | I14: 120 | J14: 0.15 | K14: =IF(OR(H14="",J14="",J14=0),"",H14*J14) | L14: Home Depot | M14: Generic 14 AWG tracer | O14: Confirmed | P14: medium | Q14: Recommended — verify if required by local code | Tracer wire — verify if required by code | Ціна збір: 2026-05-28
A15: 11 | B15: Site / Trenching | C15: Sewer | D15: Warning Tape Detectable | E15: 'CAUTION SEWER' | F15: rolls | G15: 1 | H15: 1 | I15: 1 | J15: 15 | K15: =IF(OR(H15="",J15="",J15=0),"",H15*J15) | L15: Home Depot | M15: Generic detectable | O15: Confirmed | P15: medium | Q15: 'CAUTION SEWER' | Ціна збір: 2026-05-28
A16: 12 | B16: Site / Trenching | C16: Sewer | D16: Wall / Foundation Sleeve 4" | E16: Slab penetration | F16: pcs | G16: 1 | H16: 1 | I16: 1 | J16: 25 | K16: =IF(OR(H16="",J16="",J16=0),"",H16*J16) | L16: Home Depot | M16: 4" PVC sleeve | O16: TBD | P16: low | Q16: Slab penetration | Ціна збір: 2026-05-28
A17: 13 | B17: Site / Trenching | C17: Sewer | D17: Concrete Patch Material | E17: 50 lb bag | F17: bags | G17: 1 | H17: 2 | I17: 3 | J17: 9 | K17: =IF(OR(H17="",J17="",J17=0),"",H17*J17) | L17: Home Depot | M17: Quikrete / Sakrete | O17: TBD | P17: medium | Q17: 50 lb bag | Ціна збір: 2026-05-28
A18: 14 | B18: Site / Trenching | C18: Sewer | D18: Test Caps / Cleanout Plugs allowance | E18: Для rough-in / pressure testing | F18: set | G18: 1 | H18: 1 | I18: 2 | J18: 25 | K18: =IF(OR(H18="",J18="",J18=0),"",H18*J18) | L18: Home Depot | M18: Generic 4" caps allowance | O18: Confirmed | P18: medium | Q18: ДОДАНО (review): для тестування pipe ends | ДОДАНО: test caps/plugs для pipe ends | Ціна збір: 2026-05-28
A19: 15 | B19: Site / Trenching | C19: Water Supply | D19: Main Water Supply Pipe | E19: PEX-A 1" coil | F19: linear ft | G19: 100 | H19: 110 | I19: 120 | J19: 1.45 | K19: =IF(OR(H19="",J19="",J19=0),"",H19*J19) | L19: Home Depot | M19: SharkBite UA80W100 PEX-A 1" | N19: https://www.homedepot.com/p/SharkBite-1-in-x-100-ft-Coil-White-PEX-A-Pipe-UA80W100/316358329 | O19: Confirmed | P19: high | Q19: 100 ft підтверджено | $1.45/LF ($145 per 100ft coil). Alt: copper L $4-5/LF | Ціна збір: 2026-05-28
A20: 16 | B20: Site / Trenching | C20: Water Supply | D20: PEX-A UV Protective Sleeve | E20: HDPE для buried PEX | F20: linear ft | G20: 100 | H20: 110 | I20: 120 | J20: 1 | K20: =IF(OR(H20="",J20="",J20=0),"",H20*J20) | L20: Home Depot / specialty | M20: HDPE protective sleeve | O20: Confirmed | P20: medium | Q20: PEX-A degrades on UV — required для buried sections | PEX-A UV protection for buried | Ціна збір: 2026-05-28
A21: 17 | B21: Site / Trenching | C21: Water Supply | D21: Main Shut-off Valve (ADU) 1" | E21: Brass ball, full port | F21: pcs | G21: 1 | H21: 1 | I21: 1 | J21: 30 | K21: =IF(OR(H21="",J21="",J21=0),"",H21*J21) | L21: Home Depot | M21: Brass ball valve 1" | O21: Confirmed | P21: medium | Q21: Full port, lead-free | Ціна збір: 2026-05-28
A22: 18 | B22: Site / Trenching | C22: Water Supply | D22: Brass Union Connector | E22: Tap point + ADU connection | F22: pcs | G22: 1 | H22: 2 | I22: 2 | J22: 20 | K22: =IF(OR(H22="",J22="",J22=0),"",H22*J22) | L22: Home Depot | M22: Brass union 1" | O22: Confirmed | P22: medium | Q22: Tap point + ADU connection | Ціна збір: 2026-05-28
A23: 19 | B23: Site / Trenching | C23: Water Supply | D23: Water Meter (separate) | E23: Якщо ADU має окремий meter | F23: pcs | G23: 0 | H23: 0 | I23: 1 | J23: 250 | K23: =IF(OR(H23="",J23="",J23=0),"",H23*J23) | L23: Special Order / utility | M23: Badger / Neptune meter | O23: Optional | P23: low | Q23: OPTIONAL — verify with utility / town. Не входить в baseline total | OPTIONAL — verify з utility / town | Ціна збір: 2026-05-28
A24: 20 | B24: Site / Trenching | C24: Water Supply | D24: Water Fittings / Couplings | E24: PEX brass crimp pack | F24: pack | G24: 1 | H24: 2 | I24: 3 | J24: 35 | K24: =IF(OR(H24="",J24="",J24=0),"",H24*J24) | L24: Home Depot | M24: PEX brass crimp pack | O24: Confirmed | P24: medium | Q24: Fittings assortment | Ціна збір: 2026-05-28
A25: 21 | B25: Site / Trenching | C25: Water Supply | D25: Pipe Sleeves | E25: Slab/wall penetration | F25: pcs | G25: 2 | H25: 3 | I25: 4 | J25: 7 | K25: =IF(OR(H25="",J25="",J25=0),"",H25*J25) | L25: Home Depot | M25: Generic 1" sleeve | O25: TBD | P25: medium
A26: 22 | B26: Site / Trenching | C26: Water Supply | D26: Pipe Insulation (above-grade) | E26: Foam tube 1" | F26: linear ft | G26: 30 | H26: 50 | I26: 80 | J26: 0.7 | K26: =IF(OR(H26="",J26="",J26=0),"",H26*J26) | L26: Home Depot | M26: Armaflex foam 1" | O26: TBD | P26: medium | Q26: Above-grade insulation | Ціна збір: 2026-05-28
A27: 23 | B27: Site / Trenching | C27: Water Supply | D27: Tracer Wire 14 AWG (water) | E27: Locator wire для non-metallic | F27: linear ft | G27: 100 | H27: 110 | I27: 120 | J27: 0.15 | K27: =IF(OR(H27="",J27="",J27=0),"",H27*J27) | L27: Home Depot | M27: Generic 14 AWG tracer | O27: Confirmed | P27: medium | Q27: Recommended — verify if required by local code | Tracer wire — verify if required by code | Ціна збір: 2026-05-28
A28: 24 | B28: Site / Trenching | C28: Water Supply | D28: Warning Tape (water) | E28: 'CAUTION WATER' | F28: rolls | G28: 1 | H28: 1 | I28: 1 | J28: 12 | K28: =IF(OR(H28="",J28="",J28=0),"",H28*J28) | L28: Home Depot | M28: Generic 'WATER' tape | O28: Confirmed | P28: medium
A29: 25 | B29: Site / Trenching | C29: Water Supply | D29: Bedding Material | E29: Sand bed під pipe | F29: cu yd | G29: 1 | H29: 2 | I29: 3 | J29: 45 | K29: =IF(OR(H29="",J29="",J29=0),"",H29*J29) | L29: Aggregate yard | M29: Aggregate yard | O29: TBD | P29: medium | Q29: Sand bedding | Ціна збір: 2026-05-28
A30: 26 | B30: Site / Trenching | C30: Water Supply | D30: Pressure Regulator / Backflow | E30: Якщо street >80 PSI | F30: pcs | G30: 0 | H30: 1 | I30: 1 | J30: 100 | K30: =IF(OR(H30="",J30="",J30=0),"",H30*J30) | L30: Home Depot | M30: Watts / Honeywell PRV | O30: TBD | P30: low | Q30: If street >80 PSI | Ціна збір: 2026-05-28
A31: 27 | B31: Site / Trenching | C31: Water Supply | D31: Pressure Test Cap / Plug Set | E31: Для rough-in pressure test | F31: set | G31: 1 | H31: 1 | I31: 1 | J31: 20 | K31: =IF(OR(H31="",J31="",J31=0),"",H31*J31) | L31: Home Depot | M31: Generic test cap set | O31: Confirmed | P31: medium | Q31: ДОДАНО (review): для rough-in testing | ДОДАНО: pressure test caps | Ціна збір: 2026-05-28
A32: 28 | B32: Site / Trenching | C32: Water Supply | D32: Ball Valve Access Box | E32: Якщо shut-off зовні / underground | F32: pcs | G32: 0 | H32: 1 | I32: 1 | J32: 25 | K32: =IF(OR(H32="",J32="",J32=0),"",H32*J32) | L32: Home Depot | M32: Generic valve access box | O32: TBD | P32: medium | Q32: ДОДАНО (review): access для outdoor shut-off | ДОДАНО: outdoor shut-off access | Ціна збір: 2026-05-28
A33: 29 | B33: Site / Trenching | C33: Water Supply | D33: Pipe Clamps / Supports | E33: Для above-grade sections | F33: pack | G33: 1 | H33: 1 | I33: 2 | J33: 20 | K33: =IF(OR(H33="",J33="",J33=0),"",H33*J33) | L33: Home Depot | M33: Generic pipe clamps pack | O33: Confirmed | P33: medium | Q33: ДОДАНО (review) | ДОДАНО: above-grade pipe supports | Ціна збір: 2026-05-28
A34: 30 | B34: Site / Trenching | C34: Electrical Feed | D34: Electrical Conduit (feeder) | E34: Schedule 40 PVC 2" | F34: linear ft | G34: 50 | H34: 60 | I34: 70 | J34: 1.1 | K34: =IF(OR(H34="",J34="",J34=0),"",H34*J34) | L34: Home Depot | M34: Cantex / Carlon Sch40 2" | O34: Confirmed | P34: medium | Q34: 50 ft підтверджено | $11 per 10ft. Sch 40 PVC | Ціна збір: 2026-05-28
A35: 31 | B35: Site / Trenching | C35: Electrical Feed | D35: PVC 90° Sweeps Long-Radius 2" | E35: Bends in trench | F35: pcs | G35: 2 | H35: 3 | I35: 4 | J35: 20 | K35: =IF(OR(H35="",J35="",J35=0),"",H35*J35) | L35: Home Depot | M35: Cantex / Carlon long-radius | O35: Confirmed | P35: medium | Q35: Long-radius для cable pulling | 90° LR sweep для cable pulling | Ціна збір: 2026-05-28
A36: 32 | B36: Site / Trenching | C36: Electrical Feed | D36: PVC 45° Sweeps 2" | E36: Transitions | F36: pcs | G36: 1 | H36: 2 | I36: 3 | J36: 15 | K36: =IF(OR(H36="",J36="",J36=0),"",H36*J36) | L36: Home Depot | M36: Cantex / Carlon | O36: Confirmed | P36: medium | Q36: 45° sweep | Ціна збір: 2026-05-28
A37: 33 | B37: Site / Trenching | C37: Electrical Feed | D37: PVC Expansion Fitting 2" | E37: Thermal expansion compensation | F37: pcs | G37: 1 | H37: 1 | I37: 1 | J37: 25 | K37: =IF(OR(H37="",J37="",J37=0),"",H37*J37) | L37: Home Depot | M37: Cantex expansion | O37: Confirmed | P37: medium | Q37: Recommended — verify if required by local code | Thermal expansion — verify if req'd | Ціна збір: 2026-05-28
A38: 34 | B38: Site / Trenching | C38: Electrical Feed | D38: PVC Conduit Cement | E38: Solvent weld for PVC | F38: cans | G38: 1 | H38: 1 | I38: 1 | J38: 10 | K38: =IF(OR(H38="",J38="",J38=0),"",H38*J38) | L38: Home Depot | M38: Oatey PVC cement | O38: Confirmed | P38: medium | Q38: Conduit solvent weld | Ціна збір: 2026-05-28
A39: 35 | B39: Site / Trenching | C39: Electrical Feed | D39: Feeder Wire | E39: Cu SER 4-4-4-6 (base) OR Al SER 2-2-2-4 | F39: linear ft | G39: 50 | H39: 60 | I39: 70 | J39: 8.78 | K39: =IF(OR(H39="",J39="",J39=0),"",H39*J39) | L39: Home Depot / specialty | M39: Cu SER 4-4-4-6 (base) / Al SER 2-2-2-4 (alt) | N39: https://www.wireandcableyourway.com/4-4-4-6-copper-ser-service-entrance-cable | O39: TBD | P39: high | Q39: TBD by electrician / load calculation. Cu SER ~$8.78/LF, Al SER ~$3.50/LF (-$315 з 60 LF). Final type/size pendant on ADU load calc | TBD by electrician/load calc. Cu $8.78/LF, Al ~$3.50/LF (-$315) | Ціна збір: 2026-05-28
A40: 36 | B40: Site / Trenching | C40: Electrical Feed | D40: Disconnect Switch (exterior) | E40: 100A non-fusible if req'd | F40: pcs | G40: 0 | H40: 1 | I40: 1 | J40: 45 | K40: =IF(OR(H40="",J40="",J40=0),"",H40*J40) | L40: Home Depot | M40: Square D / Eaton 100A | O40: TBD | P40: medium | Q40: Non-fusible exterior if req'd | Ціна збір: 2026-05-28
A41: 37 | B41: Site / Trenching | C41: Electrical Feed | D41: Ground Rod 8 ft Copper-clad | E41: Driven rod | F41: pcs | G41: 1 | H41: 1 | I41: 2 | J41: 18 | K41: =IF(OR(H41="",J41="",J41=0),"",H41*J41) | L41: Home Depot | M41: Copper-clad 8 ft rod | O41: Confirmed | P41: medium | Q41: Driven ground rod | Ціна збір: 2026-05-28
...

Sheet 03_Raised_Floor_System
A1: Phase 2 — Raised Floor System (§17)
A2: Vapor barrier + sleepers + joists + subfloor (10")
A4: # | B4: Phase | C4: Категорія | D4: Item / Material | E4: Spec / Опис | F4: Unit | G4: Qty (Low) | H4: Qty (Mid) | I4: Qty (High) | J4: Unit Price ($) | K4: Total ($) | L4: Source | M4: SKU / Model | N4: URL | O4: Status | P4: Confidence | Q4: Notes
A5: 1 | B5: Floor System | C5: Moisture Control | D5: Vapor / Moisture Barrier | E5: 6-mil poly | F5: sq ft | G5: 315 | H5: 350 | I5: 380 | J5: 0.1 | K5: =IF(OR(H5="",J5="",J5=0),"",H5*J5) | L5: Home Depot | M5: Husky / generic 6-mil poly | O5: Confirmed | P5: medium | Q5: 10" raised over slab | $0.10/sf. 10x100 roll ~$80-100 | Ціна збір: 2026-05-28
A6: 2 | B6: Floor System | C6: Lumber | D6: Pressure-treated Sleepers | E6: 2x4 PT laid flat as bearing | F6: linear ft | G6: 200 | H6: 260 | I6: 320 | J6: 0.95 | K6: =IF(OR(H6="",J6="",J6=0),"",H6*J6) | L6: Home Depot | M6: 2x4 PT SPF/SYP | O6: Confirmed | P6: medium | Q6: Bearing surface для joists на slab | PT для bearing на slab. 8ft ~$7-8 | Ціна збір: 2026-05-28
A7: 3 | B7: Floor System | C7: Lumber | D7: Floor Joists | E7: 2x10 SPF/HF @ 16" OC, 15 ft span | F7: linear ft | G7: 240 | H7: 280 | I7: 340 | J7: 1.85 | K7: =IF(OR(H7="",J7="",J7=0),"",H7*J7) | L7: Home Depot | M7: 2x10 #2 SPF/HF 16 ft | N7: https://www.homedepot.com/p/2-in-x-10-in-x-16-ft-2-Premium-Grade-SPF-Dimensional-Lumber-201673/100016326 | O7: Confirmed | P7: high | Q7: Final joist size/span to be verified by contractor/engineer based on actual support layout | $1.85/LF. SPF 2x10 16ft ~$30/piece (Doug Fir ~$36.63/piece ref). | Ціна збір: 2026-05-28
A8: 4 | B8: Floor System | C8: Lumber | D8: Rim Joists | E8: 2x10 PT за perimeter | F8: linear ft | G8: 60 | H8: 72 | I8: 80 | J8: 2.2 | K8: =IF(OR(H8="",J8="",J8=0),"",H8*J8) | L8: Home Depot | M8: 2x10 PT for perimeter | O8: Confirmed | P8: medium | Q8: PT lumber required where wood contacts concrete or moisture-prone areas | PT для rim on concrete contact | Ціна збір: 2026-05-28
A9: 5 | B9: Floor System | C9: Lumber | D9: Blocking | E9: 2x10 mid-span | F9: linear ft | G9: 30 | H9: 50 | I9: 70 | J9: 1.85 | K9: =IF(OR(H9="",J9="",J9=0),"",H9*J9) | L9: Home Depot | M9: 2x10 SPF blocking | O9: Confirmed | P9: medium | Q9: Same as joists | Ціна збір: 2026-05-28
A10: 6 | B10: Floor System | C10: Hardware | D10: Joist Hangers / Connectors | E10: Simpson LUS210 | F10: pcs | G10: 30 | H10: 50 | I10: 70 | J10: 4 | K10: =IF(OR(H10="",J10="",J10=0),"",H10*J10) | L10: Home Depot | M10: Simpson LUS210 | O10: Confirmed | P10: medium | Q10: Joist hanger for 2x10. $3.50-4.50 each | Ціна збір: 2026-05-28
A11: 7 | B11: Floor System | C11: Hardware | D11: Concrete Anchors (PT to slab) | E11: Wedge / Tapcon 1/2" | F11: pcs | G11: 40 | H11: 60 | I11: 80 | J11: 1.5 | K11: =IF(OR(H11="",J11="",J11=0),"",H11*J11) | L11: Home Depot | M11: Tapcon 1/2" wedge | O11: Confirmed | P11: medium | Q11: Concrete anchor PT to slab | Ціна збір: 2026-05-28
A12: 8 | B12: Floor System | C12: Insulation (floor) | D12: Insulation R-30 batt or Rigid | E12: Batt R-30 between joists | F12: sq ft | G12: 315 | H12: 330 | I12: 350 | J12: 1.61 | K12: =IF(OR(H12="",J12="",J12=0),"",H12*J12) | L12: Home Depot | M12: Owens Corning R-30 EcoTouch 16" OC unfaced | N12: https://www.homedepot.com/p/Owens-Corning-R-30-EcoTouch-PINK-Unfaced-Fiberglass-Insulation-Batt-16-in-x-48-in-BU74/300147480 | O12: Confirmed | P12: high | Q12: Verify floor insulation type: batt vs rigid foam depending on moisture and floor assembly | $1.61/sf. R-30 unfaced 16x48. CA Title 24 compliant | Ціна збір: 2026-05-28
A13: 9 | B13: Floor System | C13: Subfloor | D13: Plywood Subfloor | E13: 3/4" T&G CDX | F13: sq ft | G13: 315 | H13: 350 | I13: 380 | J13: 1.35 | K13: =IF(OR(H13="",J13="",J13=0),"",H13*J13) | L13: Home Depot | M13: CDX 3/4" T&G plywood | N13: https://www.homedepot.com/p/3-4-in-x-4-ft-x-8-ft-CDX-Pine-Plywood-1060/202088096 | O13: Confirmed | P13: high | Q13: $1.35/sf. 4x8 = $43/sheet (LENCO ref $44.95) | Ціна збір: 2026-05-28
A14: 10 | B14: Floor System | C14: Adhesives/Fasteners | D14: Construction Adhesive | E14: PL Premium subfloor | F14: tubes | G14: 6 | H14: 10 | I14: 14 | J14: 10 | K14: =IF(OR(H14="",J14="",J14=0),"",H14*J14) | L14: Home Depot | M14: Loctite PL Premium 10oz | O14: Confirmed | P14: medium | Q14: Subfloor adhesive | Ціна збір: 2026-05-28
A15: 11 | B15: Floor System | C15: Adhesives/Fasteners | D15: Subfloor Screws | E15: 3" #8 deck/subfloor | F15: lb | G15: 5 | H15: 8 | I15: 12 | J15: 6 | K15: =IF(OR(H15="",J15="",J15=0),"",H15*J15) | L15: Home Depot | M15: GRK / generic 3" #8 | O15: Confirmed | P15: medium | Q15: Часто продаються в 5 lb або 10 lb boxes | Subfloor deck screws per lb. 5 lb box ~$30 | Ціна збір: 2026-05-28
A16: 12 | B16: Floor System | C16: Sealants | D16: Foam Sealant / Caulk | E16: Air gap sealing | F16: cans | G16: 3 | H16: 5 | I16: 7 | J16: 6 | K16: =IF(OR(H16="",J16="",J16=0),"",H16*J16) | L16: Home Depot | M16: Great Stuff window/door | O16: Confirmed | P16: medium | Q16: Foam sealant | Ціна збір: 2026-05-28
A17: 13 | B17: Floor System | C17: Transitions | D17: Thresholds & Transitions | E17: Entry, French door, bathroom, exterior step | F17: pcs | G17: 3 | H17: 4 | I17: 5 | J17: 25 | K17: =IF(OR(H17="",J17="",J17=0),"",H17*J17) | L17: Home Depot | M17: Generic aluminum threshold 36" | O17: TBD | P17: medium | Q17: §17.4. Не дублювати з Phase 12 (decorative transitions only) | Entry, French door, bathroom, exterior step | Ціна збір: 2026-05-28
A18: 14 | B18: Floor System | C18: Sealing | D18: Sill Seal Foam Gasket | E18: 1x50 ft roll, між PT і slab | F18: rolls | G18: 1 | H18: 2 | I18: 3 | J18: 12 | K18: =IF(OR(H18="",J18="",J18=0),"",H18*J18) | L18: Home Depot | M18: Owens Corning / TVM sill seal 1x50 | O18: Confirmed | P18: medium | Q18: Air sealing | ДОДАНО: foam gasket між PT і slab | Ціна збір: 2026-05-28
A19: 15 | B19: Floor System | C19: Slab Prep | D19: Self-leveling Compound | E19: Allowance only — partial leveling | F19: bags | G19: 0 | H19: 4 | I19: 10 | J19: 35 | K19: =IF(OR(H19="",J19="",J19=0),"",H19*J19) | L19: Home Depot | M19: Mapei Planipatch 25 lb | O19: TBD | P19: medium | Q19: §33.22. Якщо full leveling req'd — qty зростає significantly | ДОДАНО: $35/bag, ~25 sf @ 1/8". Партіальне выравнивание | Ціна збір: 2026-05-28
A20: 16 | B20: Floor System | C20: Slab Prep | D20: Concrete Sealer / DryLok | E20: Optional moisture mitigation | F20: gal | G20: 0 | H20: 0 | I20: 5 | J20: 45 | K20: =IF(OR(H20="",J20="",J20=0),"",H20*J20) | L20: Home Depot | M20: DryLok concrete sealer 5 gal | O20: TBD | P20: medium | Q20: §33.23 verify moisture conditions. Baseline 0 | ДОДАНО: $45/gal, baseline qty=0 — only if §33.23 moisture issue | Ціна збір: 2026-05-28
A21: 17 | B21: Floor System | C21: Sealants | D21: Acoustical / Sound Caulk | E21: Floor joints sound dampening | F21: tubes | G21: 0 | H21: 3 | I21: 6 | J21: 12 | K21: =IF(OR(H21="",J21="",J21=0),"",H21*J21) | L21: Home Depot | M21: OSI ProSeries acoustical 28oz | O21: TBD | P21: medium | Q21: Optional | ДОДАНО: optional sound dampening | Ціна збір: 2026-05-28
A22: 18 | B22: Floor System | C22: Moisture Control | D22: Vapor Barrier Seam Tape | E22: Для overlap joints poly | F22: rolls | G22: 1 | H22: 1 | I22: 2 | J22: 15 | K22: =IF(OR(H22="",J22="",J22=0),"",H22*J22) | L22: Home Depot | M22: Stego seam tape / generic | O22: Confirmed | P22: medium | Q22: ДОДАНО (review): Stego/generic seam tape | ДОДАНО: для overlap vapor barrier joints | Ціна збір: 2026-05-28
A23: 19 | B23: Floor System | C23: Insulation (floor) | D23: Insulation Supports / Wire Supports | E23: Для утримання batt між joists | F23: pack | G23: 1 | H23: 2 | I23: 3 | J23: 9 | K23: =IF(OR(H23="",J23="",J23=0),"",H23*J23) | L23: Home Depot | M23: Owens Corning insul support wires | O23: Confirmed | P23: medium | Q23: ДОДАНО (review): тримає R-30 batt вгору | ДОДАНО: тримає R-30 batt між joists | Ціна збір: 2026-05-28
A24: 20 | B24: Floor System | C24: Hardware | D24: Composite / Plastic Shims | E24: Для вирівнювання sleepers/joists | F24: pack | G24: 1 | H24: 2 | I24: 3 | J24: 10 | K24: =IF(OR(H24="",J24="",J24=0),"",H24*J24) | L24: Home Depot | M24: Generic composite shims pack | O24: Confirmed | P24: medium | Q24: ДОДАНО (review) | ДОДАНО: для leveling sleepers/joists | Ціна збір: 2026-05-28
A25: 21 | B25: Floor System | C25: Hardware | D25: Structural Screws / Lag Screws | E25: SDS / Ledgerlok для rim-joist | F25: box | G25: 1 | H25: 1 | I25: 2 | J25: 25 | K25: =IF(OR(H25="",J25="",J25=0),"",H25*J25) | L25: Home Depot | M25: Simpson SDS / Ledgerlok box | O25: Confirmed | P25: medium | Q25: ДОДАНО (review): для connections without hangers | ДОДАНО: structural screws для rim-joist connections | Ціна збір: 2026-05-28
A26: 22 | B26: Floor System | C26: Access / Utility | D26: Small Access Panel allowance | E26: 12x12 PVC/металевий | F26: pcs | G26: 0 | H26: 1 | I26: 2 | J26: 22 | K26: =IF(OR(H26="",J26="",J26=0),"",H26*J26) | L26: Home Depot | M26: Generic 12x12 PVC access panel | O26: TBD | P26: medium | Q26: ДОДАНО (review): для доступу до MEP під підлогою | ДОДАНО: MEP access під raised floor | Ціна збір: 2026-05-28
C28: ПІДСУМОК ФАЗИ | K28: =SUM(K5:K26)

Sheet 04_Framing
A1: Phase 3 — Framing (§18)
A2: Left wall +21ft + interior partitions + headers
A4: # | B4: Phase | C4: Категорія | D4: Item / Material | E4: Spec / Опис | F4: Unit | G4: Qty (Low) | H4: Qty (Mid) | I4: Qty (High) | J4: Unit Price ($) | K4: Total ($) | L4: Source | M4: SKU / Model | N4: URL | O4: Status | P4: Confidence | Q4: Notes
A5: 1 | B5: Framing | C5: Studs/Plates | D5: 2x4 Studs (8 ft) | E5: SPF #2, wall framing | F5: pcs | G5: 75 | H5: 90 | I5: 110 | J5: 4.5 | K5: =IF(OR(H5="",J5="",J5=0),"",H5*J5) | L5: Home Depot | M5: 2x4 SPF #2 8ft | O5: Confirmed | P5: medium | Q5: 95-105 LF wall × 0.75 + 20-25% overhead. Включає left wall +21 LF + utility + openings | $4.50/each Bay Area premium. Menards ref $3.64 + ~25% CA | Ціна збір: 2026-05-28
A6: 2 | B6: Framing | C6: Studs/Plates | D6: 2x6 Studs (8 ft) — wet wall | E6: Для bathroom plumbing wall | F6: pcs | G6: 5 | H6: 8 | I6: 12 | J6: 7 | K6: =IF(OR(H6="",J6="",J6=0),"",H6*J6) | L6: Home Depot | M6: 2x6 SPF #2 8ft | O6: TBD | P6: medium | Q6: Depends on final bathroom/laundry layout — wet wall behind shower/vanity/laundry | Wet wall studs — final per bathroom layout | Ціна збір: 2026-05-28
A7: 3 | B7: Framing | C7: Studs/Plates | D7: Cripple / Jack / King Studs | E7: Allowance для openings | F7: pcs | G7: 15 | H7: 20 | I7: 28 | J7: 4.5 | K7: =IF(OR(H7="",J7="",J7=0),"",H7*J7) | L7: Home Depot | M7: 2x4 SPF #2 8ft (jack/king/cripple) | O7: Confirmed | P7: medium | Q7: Для 12+ framed openings | Same as standard 2x4, allowance для openings | Ціна збір: 2026-05-28
A8: 4 | B8: Framing | C8: Studs/Plates | D8: PT Bottom Plates | E8: Pressure-treated 2x4 — на subfloor edge | F8: linear ft | G8: 65 | H8: 75 | I8: 85 | J8: 0.95 | K8: =IF(OR(H8="",J8="",J8=0),"",H8*J8) | L8: Home Depot | M8: 2x4 PT | O8: Confirmed | P8: medium | Q8: PT де lumber contacts moisture-prone area | PT bottom plate per LF | Ціна збір: 2026-05-28
A9: 5 | B9: Framing | C9: Studs/Plates | D9: Top / Bottom Plates (regular) | E9: 2x4 SPF (double top + bottom) | F9: linear ft | G9: 130 | H9: 150 | I9: 170 | J9: 0.56 | K9: =IF(OR(H9="",J9="",J9=0),"",H9*J9) | L9: Home Depot | M9: 2x4 SPF #2 | O9: Confirmed | P9: medium | Q9: $0.56/LF ($4.50/8ft). Regular plate stock | Ціна збір: 2026-05-28
A10: 6 | B10: Framing | C10: Headers | D10: Standard Headers (2x6) | E10: Above standard openings (windows, doors) | F10: linear ft | G10: 20 | H10: 30 | I10: 40 | J10: 0.88 | K10: =IF(OR(H10="",J10="",J10=0),"",H10*J10) | L10: Home Depot | M10: 2x6 SPF #2 | O10: Confirmed | P10: medium | Q10: Structural sizing — final per engineer | $0.88/LF ($7/8ft). Standard window/door headers | Ціна збір: 2026-05-28
A11: 7 | B11: Framing | C11: Headers | D11: Engineered LVL Header | E11: Для French door (~6ft) + folding 8ft | F11: linear ft | G11: 12 | H11: 16 | I11: 20 | J11: 6 | K11: =IF(OR(H11="",J11="",J11=0),"",H11*J11) | L11: Home Depot / specialty | M11: LVL 1.75x7.25 engineered | N11: https://www.homedepot.com/b/Lumber-Composites-Engineered-Wood-Products/LVL/N-5yc1vZcb73Z1z0xv6e | O11: TBD | P11: medium | Q11: Final size depends on opening width, load above, existing roof/wall structure | LVL header для French door + folding 8ft. Final size per engineer | Ціна збір: 2026-05-28
A12: 8 | B12: Framing | C12: Blocking | D12: Blocking Lumber (2x4) | E12: 12 типів blocking per §18.3 | F12: linear ft | G12: 40 | H12: 60 | I12: 80 | J12: 0.56 | K12: =IF(OR(H12="",J12="",J12=0),"",H12*J12) | L12: Home Depot | M12: 2x4 SPF #2 blocking | O12: Confirmed | P12: medium | Q12: Cabinets/vanity/W-D/WH straps/TV/doors/towels/shelves... | Same as plates stock | Ціна збір: 2026-05-28
A13: 9 | B13: Framing | C13: Backing | D13: Drywall Backing / Nailers | E13: Inside corners + T-intersections | F13: linear ft | G13: 20 | H13: 30 | I13: 40 | J13: 0.56 | K13: =IF(OR(H13="",J13="",J13=0),"",H13*J13) | L13: Home Depot | M13: 2x4 SPF #2 nailer | O13: Confirmed | P13: medium | Q13: Для drywall attachment points | Drywall backing per LF | Ціна збір: 2026-05-28
A14: 10 | B14: Framing | C14: Hardware | D14: Simpson Connectors / Brackets | E14: L, T, A35 mixed | F14: pcs | G14: 20 | H14: 30 | I14: 40 | J14: 3 | K14: =IF(OR(H14="",J14="",J14=0),"",H14*J14) | L14: Home Depot | M14: Simpson mixed pack | O14: TBD | P14: medium | Q14: L, T, A35 mixed connectors | Ціна збір: 2026-05-28
A15: 11 | B15: Framing | C15: Hardware | D15: Hold-downs Simpson HDU2 allowance | E15: Allowance — TBD per structural engineer | F15: pcs | G15: 0 | H15: 4 | I15: 6 | J15: 30 | K15: =IF(OR(H15="",J15="",J15=0),"",H15*J15) | L15: Home Depot | M15: Simpson HDU2-SDS2.5 | O15: TBD | P15: medium | Q15: §33.25 — verify shear wall requirement | Hold-down. $25-35 each. Allowance, TBD per engineer | Ціна збір: 2026-05-28
A16: 12 | B16: Framing | C16: Hardware | D16: Metal Protection Plates | E16: Stud guards 1.5x5 за trades | F16: pcs | G16: 20 | H16: 30 | I16: 40 | J16: 0.5 | K16: =IF(OR(H16="",J16="",J16=0),"",H16*J16) | L16: Home Depot | M16: Generic 16-gauge stud guard | O16: TBD | P16: medium | Q16: Nail protection plate for trades | Ціна збір: 2026-05-28
A17: 13 | B17: Framing | C17: Hardware | D17: Composite / Wood Shims | E17: Для вирівнювання walls/openings | F17: pack | G17: 1 | H17: 2 | I17: 4 | J17: 10 | K17: =IF(OR(H17="",J17="",J17=0),"",H17*J17) | L17: Home Depot | M17: Generic composite/wood shims pack | O17: Confirmed | P17: medium | Q17: ДОДАНО (review): wall plumbing і opening setting | ДОДАНО (review): для wall plumbing і opening setting | Ціна збір: 2026-05-28
A18: 14 | B18: Framing | C18: Anchors | D18: Anchor Bolts 1/2 × 10 galvanized | E18: Для sill/perimeter/structural conditions | F18: pcs | G18: 12 | H18: 20 | I18: 30 | J18: 1 | K18: =IF(OR(H18="",J18="",J18=0),"",H18*J18) | L18: Home Depot | M18: Simpson / generic 1/2 × 10 galv | O18: TBD | P18: medium | Q18: Verify use: anchor bolts для sill/perimeter/structural; interior partitions on subfloor можуть use screws/nails | Anchor bolt — verify use for sill/perimeter only | Ціна збір: 2026-05-28
A19: 15 | B19: Framing | C19: Fasteners | D19: Framing Nails / Screws | E19: 16d collated, 3-1/4" mixed | F19: lb | G19: 10 | H19: 15 | I19: 20 | J19: 5 | K19: =IF(OR(H19="",J19="",J19=0),"",H19*J19) | L19: Home Depot | M19: Generic 16d collated framing nails | O19: Confirmed | P19: medium | Q19: $5/lb pneumatic collated | Ціна збір: 2026-05-28
A20: 16 | B20: Framing | C20: Fasteners | D20: Structural Screws / Header Fasteners | E20: SDS/Strong-Drive для LVL & headers | F20: box | G20: 1 | H20: 1 | I20: 2 | J20: 30 | K20: =IF(OR(H20="",J20="",J20=0),"",H20*J20) | L20: Home Depot | M20: Simpson SDS / Strong-Drive box | O20: Confirmed | P20: medium | Q20: ДОДАНО (review): для LVL/header/opening connections | ДОДАНО (review): structural screws для LVL/header | Ціна збір: 2026-05-28
A21: 17 | B21: Framing | C21: Sheathing | D21: OSB / Plywood Sheathing allowance | E21: Garage opening close-up / shear panels | F21: sheets | G21: 1 | H21: 3 | I21: 5 | J21: 30 | K21: =IF(OR(H21="",J21="",J21=0),"",H21*J21) | L21: Home Depot | M21: 3/4" OSB 4x8 sheet | O21: TBD | P21: medium | Q21: ДОДАНО (review): garage door opening closure / shear wall / backing | ДОДАНО (review): garage opening close-up + shear allowance | Ціна збір: 2026-05-28
A22: 18 | B22: Framing | C22: Adhesives | D22: Construction Adhesive (framing) | E22: PL Premium plate-to-floor | F22: tubes | G22: 3 | H22: 5 | I22: 7 | J22: 10 | K22: =IF(OR(H22="",J22="",J22=0),"",H22*J22) | L22: Home Depot | M22: Loctite PL Premium 10oz | O22: Confirmed | P22: medium | Q22: Plate-to-floor adhesive | Ціна збір: 2026-05-28
A23: 19 | B23: Framing | C23: Sealants | D23: Acoustical Sealant | E23: Bedroom/bathroom partitions sound | F23: tubes | G23: 2 | H23: 4 | I23: 6 | J23: 10 | K23: =IF(OR(H23="",J23="",J23=0),"",H23*J23) | L23: Home Depot | M23: OSI ProSeries acoustical 28oz | O23: TBD | P23: medium | Q23: Sound dampening per partition | Sound dampening для bedroom/bathroom partitions | Ціна збір: 2026-05-28
... A27: 23 | B27: Framing | C27: Bracing | D27: Temporary Bracing Lumber | E27: Для setting walls during framing | F27: linear ft | G27: 15 | H27: 25 | I27: 40 | J27: 0.56 | K27: =IF(OR(H27="",J27="",J27=0),"",H27*J27) | L27: Home Depot | M27: 2x4 SPF temp bracing (reusable) | O27: TBD | P27: medium | Q27: ДОДАНО (review): можна reuse після | ДОДАНО (review): temporary bracing, можна reuse | Ціна збір: 2026-05-28
C29: ПІДСУМОК ФАЗИ | K29: =SUM(K5:K27)

Sheet 05_Doors_Windows
A1: Phase 4 — Doors & Windows / Openings (§25)
A2: 3 windows + 5 doors + folding system
A4: # | B4: Phase | C4: Категорія | D4: Item / Material | E4: Spec / Опис | F4: Unit | G4: Qty (Low) | H4: Qty (Mid) | I4: Qty (High) | J4: Unit Price ($) | K4: Total ($) | L4: Source | M4: SKU / Model | N4: URL | O4: Status | P4: Confidence | Q4: Notes
A5: 1 | B5: Openings | C5: Windows | D5: Bathroom Window | E5: Vinyl ES, ~24×36 (TBD §33.12) | F5: pcs | G5: 1 | H5: 1 | I5: 1 | J5: 180 | K5: =IF(OR(H5="",J5="",J5=0),"",H5*J5) | L5: Home Depot | M5: JELD-WEN V-4500 24×36 white | N5: https://www.homedepot.com/b/Doors-Windows-Windows-Single-Hung-Windows/Energy-Star/N-5yc1vZas73Z1z1wgir | O5: TBD | P5: medium | Q5: Field-verify size | Bathroom window, smaller size ~$150-220 | Ціна збір: 2026-05-28
A6: 2 | B6: Openings | C6: Windows | D6: Kitchen Window | E6: Vinyl ES, ~36×48 (TBD) | F6: pcs | G6: 1 | H6: 1 | I6: 1 | J6: 300 | K6: =IF(OR(H6="",J6="",J6=0),"",H6*J6) | L6: Home Depot | M6: JELD-WEN V-4500 36×48 white | N6: https://www.homedepot.com/p/JELD-WEN-36-in-x-48-in-V-4500-Series-White-Single-Hung-Vinyl-Window-with-Fiberglass-Mesh-Screen-THDJW143900466/304848395 | O6: TBD | P6: medium | Q6: Field-verify size | Kitchen window, standard size. HD retail $250-350 | Ціна збір: 2026-05-28
A7: 3 | B7: Openings | C7: Windows | D7: Living Room Window | E7: Vinyl ES, ~36×60 (TBD) | F7: pcs | G7: 1 | H7: 1 | I7: 1 | J7: 400 | K7: =IF(OR(H7="",J7="",J7=0),"",H7*J7) | L7: Home Depot | M7: JELD-WEN V-4500 36×60 white | O7: TBD | P7: medium | Q7: Field-verify size | Living window, larger size. Premium V-4500 dealer $675 ref | Ціна збір: 2026-05-28
A8: 4 | B8: Openings | C8: Exterior Doors | D8: Main Entry Door | E8: Prehung steel 36×80 insulated | F8: pcs | G8: 1 | H8: 1 | I8: 1 | J8: 400 | K8: =IF(OR(H8="",J8="",J8=0),"",H8*J8) | L8: Home Depot | M8: Masonite Premium 6-panel 36×80 | N8: https://www.homedepot.com/p/Masonite-36-in-x-80-in-Premium-6-Panel-Right-Hand-Inswing-Primed-Steel-Prehung-Front-Exterior-Door-with-Brickmold-27105/100053184 | O8: TBD | P8: medium | Q8: Field-verify size (§33.14) | Prehung steel insulated з brickmold. $300-500 range | Ціна збір: 2026-05-28
A9: 5 | B9: Openings | C9: Exterior Doors | D9: Backyard French Door | E9: Fiberglass prehung 60×80, glazed | F9: pcs | G9: 1 | H9: 1 | I9: 1 | J9: 1500 | K9: =IF(OR(H9="",J9="",J9=0),"",H9*J9) | L9: Special Order | M9: Masonite/ThermaTru fiberglass 60×80 patio | N9: https://www.homedepot.com/b/Doors-Windows-Exterior-Doors-Patio-Doors/Masonite/60-x-80/French-Patio-Door/N-5yc1vZarqnZyqZ1z0rbkpZ1z0v1y3 | O9: Confirmed | P9: medium | Q9: Special Order. Lead 4-8 weeks. Delivery not included. Field-verify (§33.13) | Special Order. Fiberglass French. $1200-1800 range | Ціна збір: 2026-05-28
A10: 6 | B10: Openings | C10: Interior Doors | D10: Bathroom Door | E10: Prehung hollow core 30×80 | F10: pcs | G10: 1 | H10: 1 | I10: 1 | J10: 110 | K10: =IF(OR(H10="",J10="",J10=0),"",H10*J10) | L10: Home Depot | M10: Masonite hollow core 30×80 | O10: TBD | P10: medium | Q10: Verify if privacy lockset included; otherwise add separately | Prehung з privacy lock | Ціна збір: 2026-05-28
A11: 7 | B11: Openings | C11: Interior Doors | D11: Utility Closet Door | E11: 24×80 louvered bifold або slab | F11: pcs | G11: 1 | H11: 1 | I11: 1 | J11: 80 | K11: =IF(OR(H11="",J11="",J11=0),"",H11*J11) | L11: Home Depot | M11: Masonite louvered prehung 24×80 | O11: TBD | P11: medium | Q11: Final type TBD based on clearance | Або bifold louvered | Ціна збір: 2026-05-28
A12: 8 | B12: Openings | C12: Specialty Systems | D12: Closet Sliding Door System | E12: Bypass 6 ft, 2-panel | F12: system | G12: 1 | H12: 1 | I12: 1 | J12: 250 | K12: =IF(OR(H12="",J12="",J12=0),"",H12*J12) | L12: Home Depot / IKEA | M12: Home Depot bypass system 6ft | O12: TBD | P12: medium | Q12: Field-verify (§33.16) | 2-panel bypass sliding closet system | Ціна збір: 2026-05-28
A13: 9 | B13: Openings | C13: Specialty Systems | D13: Folding / Panel Door System 8 ft | E13: INTERIOR partition між bedroom і living (per §17.4) | F13: system | G13: 1 | H13: 1 | I13: 1 | J13: 3000 | K13: =IF(OR(H13="",J13="",J13=0),"",H13*J13) | L13: Special Order | M13: Mid-tier folding partition system 8ft | N13: https://homeguide.com/costs/folding-accordion-patio-doors-cost | O13: Confirmed | P13: low | Q13: Special Order INTERIOR. High variability — final cost залежить від material: accordion / bifold / glass folding / wood / track / sound level. Field-verify (§33.15) | Special Order INTERIOR partition. Variability $1500 (basic accordion) - $6000 (LaCantina-style interior). Mid $3000 для quality glass/wood folding | Ціна збір: 2026-05-28
A14: 10 | B14: Openings | C14: Weatherproofing | D14: Flashing Tape | E14: Windows + doors butyl/peel-stick | F14: rolls | G14: 2 | H14: 3 | I14: 4 | J14: 25 | K14: =IF(OR(H14="",J14="",J14=0),"",H14*J14) | L14: Home Depot | M14: Tyvek FlexWrap / 3M flashing tape | O14: Confirmed | P14: medium | Q14: Per roll | Ціна збір: 2026-05-28
A15: 11 | B15: Openings | C15: Weatherproofing | D15: Sill Pans | E15: Windows + 2 exterior doors | F15: pcs | G15: 4 | H15: 5 | I15: 5 | J15: 30 | K15: =IF(OR(H15="",J15="",J15=0),"",H15*J15) | L15: Home Depot | M15: Generic vinyl sill pan | O15: Confirmed | P15: medium | Q15: Підвищено Mid: 3 windows + entry + French = 5 openings | Per window | Ціна збір: 2026-05-28
A16: 12 | B16: Openings | C16: Weatherproofing | D16: Exterior Sealant | E16: Polyurethane caulk | F16: tubes | G16: 4 | H16: 6 | I16: 8 | J16: 8 | K16: =IF(OR(H16="",J16="",J16=0),"",H16*J16) | L16: Home Depot | M16: Sika / OSI polyurethane sealant | O16: Confirmed | P16: medium | Q16: Caulk tube | Ціна збір: 2026-05-28
A17: 13 | B17: Openings | C17: Weatherproofing | D17: Low-expansion Foam | E17: Для perimeter gaps | F17: cans | G17: 3 | H17: 4 | I17: 6 | J17: 7 | K17: =IF(OR(H17="",J17="",J17=0),"",H17*J17) | L17: Home Depot | M17: Great Stuff window/door foam | O17: Confirmed | P17: medium | Q17: Low-expansion cans | Ціна збір: 2026-05-28
A18: 14 | B18: Openings | C18: Trim | D18: Interior Casing | E18: За дверима/вікнами, 7+ openings | F18: linear ft | G18: 80 | H18: 120 | I18: 160 | J18: 0.8 | K18: =IF(OR(H18="",J18="",J18=0),"",H18*J18) | L18: Home Depot | M18: MDF / pine interior casing | O18: Confirmed | P18: medium | Q18: Per LF | Ціна збір: 2026-05-28
A19: 15 | B19: Openings | C19: Trim | D19: Exterior Trim | E19: Standard exterior molding | F19: linear ft | G19: 40 | H19: 60 | I19: 80 | J19: 1.2 | K19: =IF(OR(H19="",J19="",J19=0),"",H19*J19) | L19: Home Depot | M19: Pine/PVC exterior trim | O19: Confirmed | P19: medium | Q19: Per LF | Ціна збір: 2026-05-28
A20: 16 | B20: Openings | C20: Hardware | D20: Entry Door Lockset + Deadbolt | E20: Для main entry only | F20: set | G20: 1 | H20: 1 | I20: 1 | J20: 200 | K20: =IF(OR(H20="",J20="",J20=0),"",H20*J20) | L20: Home Depot | M20: Schlage/Kwikset Entry lockset+deadbolt | O20: Confirmed | P20: medium | Q20: Schlage/Kwikset deadbolt + handle | Entry ONLY (French door has separate multi-point in row 24) | Ціна збір: 2026-05-28
A21: 17 | B21: Openings | C21: Windows | D21: Window Screens | E21: Fiberglass mesh | F21: pcs | G21: 3 | H21: 3 | I21: 3 | J21: 40 | K21: =IF(OR(H21="",J21="",J21=0),"",H21*J21) | L21: Home Depot | M21: Generic vinyl window screen | O21: Confirmed | P21: medium | Q21: May be included with selected windows; keep as allowance until product selected | Per window. May be included з window selection | Ціна збір: 2026-05-28
A22: 18 | B22: Openings | C22: Windows | D22: Window Sills / Stools | E22: Interior trim під window | F22: pcs | G22: 3 | H22: 3 | I22: 3 | J22: 30 | K22: =IF(OR(H22="",J22="",J22=0),"",H22*J22) | L22: Home Depot | M22: Pine/MDF window sill stool | O22: Confirmed | P22: medium | Q22: Окремо від generic casing | Per window | Ціна збір: 2026-05-28
A23: 19 | B23: Openings | C23: Trim | D23: Brick Mold / Exterior Casing | E23: Для exterior openings | F23: linear ft | G23: 40 | H23: 60 | I23: 80 | J23: 1.5 | K23: =IF(OR(H23="",J23="",J23=0),"",H23*J23) | L23: Home Depot | M23: Pine brick mold exterior casing | O23: Confirmed | P23: medium | Q23: Окремо від generic exterior trim | Per LF, surrounds exterior openings | Ціна збір: 2026-05-28
A24: 20 | B24: Openings | C24: Hardware | D24: French Door Hardware | E24: Multi-point lock + handles | F24: set | G24: 1 | H24: 1 | I24: 1 | J24: 300 | K24: =IF(OR(H24="",J24="",J24=0),"",H24*J24) | L24: Special Order | M24: Multi-point lock French door set | O24: TBD | P24: medium | Q24: Специфічно для French door (§25.3) | 3-point lock + handles для French door | Ціна збір: 2026-05-28
A25: 21 | B25: Openings | C25: Hardware | D25: Weatherstripping | E25: Kit для exterior doors | F25: set | G25: 2 | H25: 2 | I25: 2 | J25: 25 | K25: =IF(OR(H25="",J25="",J25=0),"",H25*J25) | L25: Home Depot | M25: Generic kit weatherstripping | O25: Confirmed | P25: medium | Q25: Entry + French | Per exterior door | Ціна збір: 2026-05-28
... A34: 30 | B34: Openings | C34: Finish | D34: Interior Paintable Caulk | E34: Для casing/trim joints | F34: tubes | G34: 6 | H34: 8 | I34: 10 | J34: 5 | K34: =IF(OR(H34="",J34="",J34=0),"",H34*J34) | L34: Home Depot | M34: DAP Alex Plus paintable caulk | O34: Confirmed | P34: medium | Q34: ДОДАНО (review) | ДОДАНО (review): casing/trim joints | Ціна збір: 2026-05-28
C36: ПІДСУМОК ФАЗИ | K36: =SUM(K5:K34)

Sheet 06_Plumbing_Roughin
A1: Phase 5 — Plumbing Rough-in (§20)
A2: PEX supply + ABS/PVC drain + vent + fittings
A4: # | B4: Phase | C4: Категорія | D4: Item / Material | E4: Spec / Опис | F4: Unit | G4: Qty (Low) | H4: Qty (Mid) | I4: Qty (High) | J4: Unit Price ($) | K4: Total ($) | L4: Source | M4: SKU / Model | N4: URL | O4: Status | P4: Confidence | Q4: Notes
A5: 1 | B5: Plumbing R-I | C5: Supply | D5: PEX Hot/Cold Pipe 1/2" | E5: PEX-B coil 100 ft | F5: linear ft | G5: 200 | H5: 230 | I5: 260 | J5: 0.35 | K5: =IF(OR(H5="",J5="",J5=0),"",H5*J5) | L5: Home Depot | M5: SharkBite/Apollo PEX-B 1/2" 100ft | N5: https://www.homedepot.com/p/SharkBite-1-2-in-x-100-ft-Coil-Red-PEX-B-Pipe-U860R100/202033011 | O5: Confirmed | P5: high | Q5: $0.35/LF ($35/100ft coil) | Ціна збір: 2026-05-28
A6: 2 | B6: Plumbing R-I | C6: Supply | D6: PEX Hot/Cold Pipe 3/4" | E6: Main runs PEX-B | F6: linear ft | G6: 100 | H6: 120 | I6: 140 | J6: 0.7 | K6: =IF(OR(H6="",J6="",J6=0),"",H6*J6) | L6: Home Depot | M6: SharkBite PEX-B 3/4" 100ft | O6: Confirmed | P6: medium | Q6: $0.70/LF ($70/100ft coil) | Ціна збір: 2026-05-28
A7: 3 | B7: Plumbing R-I | C7: Supply | D7: PEX Fittings (assortment) | E7: Elbows, tees, couplings, crimps | F7: pack | G7: 2 | H7: 3 | I7: 4 | J7: 25 | K7: =IF(OR(H7="",J7="",J7=0),"",H7*J7) | L7: Home Depot | M7: Apollo/SharkBite PEX fittings pack | O7: Confirmed | P7: medium | Q7: Assortment: elbows, tees, couplings, crimp rings | Ціна збір: 2026-05-28
A8: 4 | B8: Plumbing R-I | C8: Supply | D8: Shut-off Valves (1/4-turn) | E8: Interior fixtures angle stops | F8: pcs | G8: 16 | H8: 19 | I8: 22 | J8: 7 | K8: =IF(OR(H8="",J8="",J8=0),"",H8*J8) | L8: Home Depot | M8: Apollo PEX-B 1/2" angle stop quarter-turn | N8: https://www.homedepot.com/p/Apollo-1-2-in-Chrome-Plated-Brass-PEX-B-Barb-x-1-4-in-Compression-Quarter-Turn-Angle-Stop-Valve-APXVA1214C/305455212 | O8: Confirmed | P8: high | Q8: Per valve, brass chrome-plated | Ціна збір: 2026-05-28
A9: 5 | B9: Plumbing R-I | C9: Drain | D9: ABS/PVC Drain Pipe 1.5" | E9: Sink/vanity drains | F9: linear ft | G9: 30 | H9: 40 | I9: 50 | J9: 0.85 | K9: =IF(OR(H9="",J9="",J9=0),"",H9*J9) | L9: Home Depot | M9: Charlotte/IPEX ABS DWV 1.5" | O9: Confirmed | P9: medium | Q9: Per LF, DWV grade | Ціна збір: 2026-05-28
A10: 6 | B10: Plumbing R-I | C10: Drain | D10: ABS/PVC Drain Pipe 2" | E10: Shower/laundry drains | F10: linear ft | G10: 40 | H10: 60 | I10: 80 | J10: 1.1 | K10: =IF(OR(H10="",J10="",J10=0),"",H10*J10) | L10: Home Depot | M10: Charlotte/IPEX ABS DWV 2" | O10: Confirmed | P10: medium | Q10: Per LF | Ціна збір: 2026-05-28
A11: 7 | B11: Plumbing R-I | C11: Drain | D11: ABS/PVC Drain Pipe 3" | E11: Branch + toilet drain | F11: linear ft | G11: 20 | H11: 30 | I11: 40 | J11: 1.8 | K11: =IF(OR(H11="",J11="",J11=0),"",H11*J11) | L11: Home Depot | M11: Charlotte/IPEX ABS DWV 3" | O11: Confirmed | P11: medium | Q11: Per LF, for toilet drain | Ціна збір: 2026-05-28
A12: 8 | B12: Plumbing R-I | C12: Drain | D12: ABS/PVC Drain Pipe 4" | E12: Main building drain | F12: linear ft | G12: 15 | H12: 20 | I12: 25 | J12: 3 | K12: =IF(OR(H12="",J12="",J12=0),"",H12*J12) | L12: Home Depot | M12: IPEX ABS DWV 4" 10ft | N12: https://www.homedepot.com/p/IPEX-4-in-x-10-ft-ABS-DWV-Cell-Core-Pipe-179687/309282462 | O12: Confirmed | P12: medium | Q12: $3/LF ($30/10ft piece). Cell core ABS | Ціна збір: 2026-05-28
A13: 9 | B13: Plumbing R-I | C13: Vent | D13: Vent Pipe | E13: ABS/PVC 1.5-2" | F13: linear ft | G13: 20 | H13: 30 | I13: 40 | J13: 0.95 | K13: =IF(OR(H13="",J13="",J13=0),"",H13*J13) | L13: Home Depot | M13: Charlotte ABS DWV 2" vent | O13: Confirmed | P13: medium | Q13: Per LF | Ціна збір: 2026-05-28
A14: 10 | B14: Plumbing R-I | C14: Fittings | D14: P-traps | E14: Sinks, shower, washer | F14: pcs | G14: 4 | H14: 4 | I14: 5 | J14: 8 | K14: =IF(OR(H14="",J14="",J14=0),"",H14*J14) | L14: Home Depot | M14: Oatey/generic P-trap kit | O14: Confirmed | P14: medium | Q14: 1.5" or 2" P-trap | Ціна збір: 2026-05-28
A15: 11 | B15: Plumbing R-I | C15: Fittings | D15: Cleanouts (interior) | E15: Body + plug | F15: pcs | G15: 2 | H15: 2 | I15: 3 | J15: 20 | K15: =IF(OR(H15="",J15="",J15=0),"",H15*J15) | L15: Home Depot | M15: Charlotte 4" ABS cleanout | O15: Confirmed | P15: medium | Q15: Body + threaded plug | Ціна збір: 2026-05-28
A16: 12 | B16: Plumbing R-I | C16: Fittings | D16: Pipe Clamps / Hangers | E16: ABS strut/strap pack | F16: pack | G16: 2 | H16: 3 | I16: 4 | J16: 15 | K16: =IF(OR(H16="",J16="",J16=0),"",H16*J16) | L16: Home Depot | M16: Sioux Chief strut/strap pack | O16: Confirmed | P16: medium | Q16: Per pack — pipe hangers/clamps | Ціна збір: 2026-05-28
A17: 13 | B17: Plumbing R-I | C17: Fittings | D17: Primer / Cement ABS-PVC | E17: Solvent weld | F17: cans | G17: 2 | H17: 3 | I17: 4 | J17: 12 | K17: =IF(OR(H17="",J17="",J17=0),"",H17*J17) | L17: Home Depot | M17: Oatey ABS primer + cement combo | O17: Confirmed | P17: medium | Q17: Per can | Ціна збір: 2026-05-28
A18: 14 | B18: Plumbing R-I | C18: Misc | D18: Washer Outlet Box | E18: Recessed, hot/cold + drain | F18: pcs | G18: 1 | H18: 1 | I18: 1 | J18: 40 | K18: =IF(OR(H18="",J18="",J18=0),"",H18*J18) | L18: Home Depot | M18: Sioux Chief / LSP washer outlet box | O18: Confirmed | P18: medium | Q18: Recessed hot/cold + drain box | Ціна збір: 2026-05-28
A19: 15 | B19: Plumbing R-I | C19: Misc | D19: Toilet Flange | E19: PVC/ABS w/ ring | F19: pcs | G19: 1 | H19: 1 | I19: 1 | J19: 12 | K19: =IF(OR(H19="",J19="",J19=0),"",H19*J19) | L19: Home Depot | M19: Oatey ABS toilet flange w/ ring | O19: Confirmed | P19: medium | Q19: Standard 3" or 4" | Ціна збір: 2026-05-28
A20: 16 | B20: Plumbing R-I | C20: Misc | D20: Water Heater Connection Kit | E20: Flex lines + fittings | F20: set | G20: 1 | H20: 1 | I20: 1 | J20: 50 | K20: =IF(OR(H20="",J20="",J20=0),"",H20*J20) | L20: Home Depot | M20: WH connection kit (flex lines + dielectric) | O20: TBD | P20: medium | Q20: Coordinate w/ Phase 15 Water Heater | Coordinate Phase 15 WH | Ціна збір: 2026-05-28
A21: 17 | B21: Plumbing R-I | C21: Misc | D21: Pipe Insulation (interior) | E21: Hot lines foam 1/2-3/4" | F21: linear ft | G21: 30 | H21: 50 | I21: 70 | J21: 0.5 | K21: =IF(OR(H21="",J21="",J21=0),"",H21*J21) | L21: Home Depot | M21: Armaflex foam 1/2"-3/4" | O21: Confirmed | P21: medium | Q21: Hot line insulation per LF | Ціна збір: 2026-05-28
A22: 18 | B22: Plumbing R-I | C22: Fittings | D22: ABS/PVC DWV Fittings | E22: Elbows, couplings, tees, sanitary tees, wyes, reducers | F22: pack | G22: 2 | H22: 3 | I22: 5 | J22: 50 | K22: =IF(OR(H22="",J22="",J22=0),"",H22*J22) | L22: Home Depot | M22: ABS DWV fittings assortment pack | O22: Confirmed | P22: medium | Q22: ДОДАНО (§20.3): drain fittings okремо | ДОДАНО: elbows, tees, sanitary tees, wyes, reducers. $50/pack | Ціна збір: 2026-05-28
A23: 19 | B23: Plumbing R-I | C23: Misc | D23: Washer Standpipe | E23: 2" 18-30" tall | F23: pcs | G23: 1 | H23: 1 | I23: 1 | J23: 15 | K23: =IF(OR(H23="",J23="",J23=0),"",H23*J23) | L23: Home Depot | M23: 2" PVC/ABS washer standpipe | O23: Confirmed | P23: medium | Q23: ДОДАНО (§20.3): окремо від outlet box | ДОДАНО (§20.3) | Ціна збір: 2026-05-28
A24: 20 | B24: Plumbing R-I | C24: Misc | D24: Dishwasher Connection Kit | E24: Tee + brass elbow + 3/8 supply | F24: set | G24: 1 | H24: 1 | I24: 1 | J24: 25 | K24: =IF(OR(H24="",J24="",J24=0),"",H24*J24) | L24: Home Depot | M24: Generic dishwasher install kit | O24: Confirmed | P24: medium | Q24: ДОДАНО (§20.3) | ДОДАНО: tee + elbow + supply line | Ціна збір: 2026-05-28
... A38: 34 | B38: Plumbing R-I | C38: Misc | D38: Water Heater Pan + Drain (cross-ref Phase 15) | E38: Залишено в Phase 15 — не дублюйте | F38: set | G38: 0 | H38: 0 | I38: 0 | J38: 0 | K38: =IF(OR(H38="",J38="",J38=0),"",H38*J38) | L38: Home Depot | M38: — | O38: Confirmed | P38: medium | Q38: ДОДАНО (review): cross-reference. Cost у Phase 15 Water Heater | ДОДАНО (review): cross-ref Phase 15. Не дублювати — qty 0 | Ціна збір: 2026-05-28
C40: ПІДСУМОК ФАЗИ | K40: =SUM(K5:K38)

Sheet 07_Electrical_Roughin
A1: Phase 6 — Electrical Rough-in (§21)
A2: ADU subpanel + Romex + boxes + devices + light fixtures
A4: # | B4: Phase | C4: Категорія | D4: Item / Material | E4: Spec / Опис | F4: Unit | G4: Qty (Low) | H4: Qty (Mid) | I4: Qty (High) | J4: Unit Price ($) | K4: Total ($) | L4: Source | M4: SKU / Model | N4: URL | O4: Status | P4: Confidence | Q4: Notes
A5: 1 | B5: Electrical R-I | C5: Panel | D5: ADU Subpanel 100A | E5: Square D QO 20-space allowance | F5: pcs | G5: 1 | H5: 1 | I5: 1 | J5: 139 | K5: =IF(OR(H5="",J5="",J5=0),"",H5*J5) | L5: Home Depot | M5: Square D QO120M100C 100A 20-space | N5: https://www.homedepot.com/p/Square-D-QO-100-Amp-20-Space-20-Circuit-Indoor-Main-Breaker-Load-Center-with-Cover-QO120M100C/100195842 | O5: Confirmed | P5: high | Q5: Final amperage by load calculation (§33.21) | $139 retail (promo $114 з HD card). 100A indoor main breaker load center | Ціна збір: 2026-05-28
A6: 2 | B6: Electrical R-I | C6: Panel | D6: Standard Breakers (non-AFCI) | E6: Single/double pole для 240V appliances + non-AFCI circuits | F6: set | G6: 1 | H6: 1 | I6: 1 | J6: 130 | K6: =IF(OR(H6="",J6="",J6=0),"",H6*J6) | L6: Home Depot | M6: Square D QO standard breakers (non-AFCI only) | O6: Confirmed | P6: medium | Q6: Тільки для circuits де AFCI не required: range, WH, mini-split, dryer, bathroom GFCI | Тільки для non-AFCI circuits: 240V (range/WH/HVAC) + bath GFCI + non-AFCI. AFCI breakers в r26 окремо | Ціна збір: 2026-05-28
A7: 3 | B7: Electrical R-I | C7: Wire | D7: Romex 12/2 (20A circuits) | E7: 250ft / 1000ft rolls NM-B | F7: linear ft | G7: 500 | H7: 600 | I7: 700 | J7: 0.65 | K7: =IF(OR(H7="",J7="",J7=0),"",H7*J7) | L7: Home Depot | M7: Southwire 12/2 NM-B Romex SIMpull | N7: https://www.homedepot.com/p/Southwire-250-ft-12-2-Solid-Romex-SIMpull-CU-NM-B-W-G-Wire-28828269/202019375 | O7: Confirmed | P7: medium | Q7: $0.65/LF (~$163 per 250ft roll). Bay Area premium | Ціна збір: 2026-05-28
A8: 4 | B8: Electrical R-I | C8: Wire | D8: Romex 14/2 (15A circuits) | E8: Lighting general NM-B | F8: linear ft | G8: 300 | H8: 400 | I8: 500 | J8: 0.45 | K8: =IF(OR(H8="",J8="",J8=0),"",H8*J8) | L8: Home Depot | M8: Southwire 14/2 NM-B Romex | O8: Confirmed | P8: medium | Q8: $0.45/LF lighter gauge | Ціна збір: 2026-05-28
A9: 5 | B9: Electrical R-I | C9: Wire | D9: 240V Cable (range/WH/HVAC) | E9: 8/3 (range) + 10/2 (WH, mini-split) | F9: linear ft | G9: 80 | H9: 120 | I9: 160 | J9: 2.5 | K9: =IF(OR(H9="",J9="",J9=0),"",H9*J9) | L9: Home Depot | M9: Southwire 8/3 + 10/2 NM-B (240V) | O9: Confirmed | P9: medium | Q9: Range 40A, WH 30A, mini-split 30A | Average $2.50/LF mixed. 8/3 для range, 10/2 для WH/HVAC | Ціна збір: 2026-05-28
A10: 6 | B10: Electrical R-I | C10: Wire | D10: Interior Conduit (where req'd) | E10: EMT/PVC 1/2-3/4" | F10: linear ft | G10: 20 | H10: 40 | I10: 60 | J10: 0.8 | K10: =IF(OR(H10="",J10="",J10=0),"",H10*J10) | L10: Home Depot | M10: Allied EMT / Cantex PVC conduit 1/2-3/4" | O10: TBD | P10: medium | Q10: Interior conduit per LF | Ціна збір: 2026-05-28
A11: 7 | B11: Electrical R-I | C11: Devices | D11: Electrical Boxes (mixed) | E11: 1-gang, 2-gang, ceiling, old-work | F11: pcs | G11: 55 | H11: 62 | I11: 70 | J11: 1.75 | K11: =IF(OR(H11="",J11="",J11=0),"",H11*J11) | L11: Home Depot | M11: Carlon plastic boxes mixed | O11: Confirmed | P11: medium | Q11: Average $1.75/box: 1g $1.50, 2g $2.50, ceiling $3, old-work $3.50, WP $12 | Ціна збір: 2026-05-28
A12: 8 | B12: Electrical R-I | C12: Devices | D12: Standard Outlets TR-rated | E12: Tamper-resistant 15A/20A | F12: pcs | G12: 25 | H12: 30 | I12: 35 | J12: 2.5 | K12: =IF(OR(H12="",J12="",J12=0),"",H12*J12) | L12: Home Depot | M12: Leviton TR-rated 15A/20A outlet | O12: Confirmed | P12: medium | Q12: CA Code 2019+ TR mandatory | Tamper-resistant per CA Code 2019+ | Ціна збір: 2026-05-28
A13: 9 | B13: Electrical R-I | C13: Devices | D13: GFCI Outlets | E13: Bath, kitchen, exterior | F13: pcs | G13: 8 | H13: 10 | I13: 12 | J13: 18 | K13: =IF(OR(H13="",J13="",J13=0),"",H13*J13) | L13: Home Depot | M13: Leviton/Eaton GFCI receptacle | O13: Confirmed | P13: medium | Q13: Final GFCI strategy TBD: protection may be provided by GFCI receptacles, GFCI breakers, or dual-function breakers | Per pc | Ціна збір: 2026-05-28
A14: 10 | B14: Electrical R-I | C14: Devices | D14: Switches / Dimmers (LED-compatible) | E14: Single/3-way mix | F14: pcs | G14: 12 | H14: 15 | I14: 18 | J14: 7 | K14: =IF(OR(H14="",J14="",J14=0),"",H14*J14) | L14: Home Depot | M14: Leviton switches + dimmers mix | O14: Confirmed | P14: medium | Q14: CA Title 24 LED dimming | $2-4 single switch, $15-25 LED dimmer. Average $7 | Ціна збір: 2026-05-28
A15: 11 | B15: Electrical R-I | C15: Devices | D15: Cover Plates | F15: pcs | G15: 55 | H15: 62 | I15: 70 | J15: 0.75 | K15: =IF(OR(H15="",J15="",J15=0),"",H15*J15) | L15: Home Depot | M15: Leviton plastic cover plates | O15: Confirmed | P15: medium | Q15: Average per cover | Ціна збір: 2026-05-28
A16: 12 | B16: Electrical R-I | C16: Devices | D16: Bathroom Fan Timer Switch | F16: pcs | G16: 1 | H16: 1 | I16: 1 | J16: 30 | K16: =IF(OR(H16="",J16="",J16=0),"",H16*J16) | L16: Home Depot | M16: Leviton bathroom fan timer switch | O16: TBD | P16: medium | Q16: Single-pole | Ціна збір: 2026-05-28
A17: 13 | B17: Electrical R-I | C17: Devices | D17: Smoke / CO Detectors | E17: Combo hardwired interconnected + battery backup | F17: pcs | G17: 2 | H17: 3 | I17: 4 | J17: 43.44 | K17: =IF(OR(H17="",J17="",J17=0),"",H17*J17) | L17: Home Depot | M17: First Alert 1039339 hardwired combo | N17: https://www.homedepot.com/p/First-Alert-Smoke-and-CO-Detector-AA-Battery-1039339/313143543 | O17: Confirmed | P17: medium | Q17: Final placement TBD. CA Code: hardwired interconnected | Smoke+CO combo. CA Code: hardwired interconnected з battery backup | Ціна збір: 2026-05-28
A18: 14 | B18: Electrical R-I | C18: Devices | D18: Weatherproof Outlets | E18: Exterior GFCI in-use cover | F18: pcs | G18: 1 | H18: 2 | I18: 2 | J18: 22 | K18: =IF(OR(H18="",J18="",J18=0),"",H18*J18) | L18: Home Depot | M18: Leviton GFCI weatherproof + in-use cover | O18: TBD | P18: medium | Q18: Exterior | Ціна збір: 2026-05-28
